<mujoco model="prosthesis_env">
  <compiler angle="radian" autolimits="true" meshdir="."/>
  <option gravity="0 0 -9.81" integrator="implicitfast" timestep="0.002"/>
  <visual>
    <global offwidth="1280" offheight="720"/>
    <headlight ambient="0.4 0.4 0.4" diffuse="0.6 0.6 0.6"/>
    <rgba haze="0.85 0.88 0.92 1"/>
  </visual>
  <asset>
    <texture name="skybox" type="skybox" builtin="gradient"
             rgb1="0.55 0.62 0.72" rgb2="0.10 0.12 0.16" width="512" height="512"/>
    <texture name="grid" type="2d" builtin="checker" rgb1="0.30 0.32 0.36"
             rgb2="0.22 0.24 0.28" width="512" height="512"/>
    <material name="grid" texture="grid" texrepeat="14 14" reflectance="0.05"/>
    <mesh name="arm_mesh" file="arm_visual.stl"/>
  </asset>
  <worldbody>
    <light pos="0 0 4" dir="0 0 -1" diffuse="0.9 0.9 0.9"/>
    <geom name="floor" type="plane" size="0 0 0.05" material="grid"/>
    <body name="mount" pos="0.0 -0.4 1.0">
      <geom name="mount_geom" type="box" size="0.045 0.045 0.045" rgba="0.30 0.30 0.35 1"/>
      <body name="arm" pos="0 0 0">
        <joint name="shoulder_flex" type="hinge" axis="0 1 0" range="-1.571 2.094"
               damping="0.8" armature="0.02"/>
        <joint name="shoulder_abduct" type="hinge" axis="1 0 0" range="-1.047 1.571"
               damping="0.8" armature="0.02"/>
        <geom name="arm_geom" type="mesh" mesh="arm_mesh" rgba="0.20 0.60 0.95 1" density="1010"/>
        <site name="ee" pos="0 0 -0.64" size="0.015" rgba="0.95 0.2 0.2 1" group="1"/>
      </body>
    </body>
    <body name="human" pos="0 0 0">
      <geom type="capsule" fromto="0 -0.4 1 0.36 -0.4 1" size="0.05" rgba="0.27 0.42 0.55 1" contype="0" conaffinity="0" group="2"/>
      <geom type="capsule" fromto="0.18 -0.4 0.49 0.18 -0.4 1.01" size="0.12" rgba="0.27 0.42 0.55 1" contype="0" conaffinity="0" group="2"/>
      <geom type="capsule" fromto="0.18 -0.4 1.02 0.18 -0.4 1.09" size="0.045" rgba="0.86 0.66 0.52 1" contype="0" conaffinity="0" group="2"/>
      <geom type="sphere" pos="0.18 -0.4 1.21" size="0.105" rgba="0.86 0.66 0.52 1" contype="0" conaffinity="0" group="2"/>
      <geom type="capsule" fromto="0.36 -0.4 1 0.4 -0.3 0.72" size="0.05" rgba="0.86 0.66 0.52 1" contype="0" conaffinity="0" group="2"/>
      <geom type="capsule" fromto="0.4 -0.3 0.72 0.34 -0.1 0.57" size="0.045" rgba="0.86 0.66 0.52 1" contype="0" conaffinity="0" group="2"/>
      <geom type="sphere" pos="0.34 -0.1 0.57" size="0.05" rgba="0.86 0.66 0.52 1" contype="0" conaffinity="0" group="2"/>
      <geom type="capsule" fromto="0.08 -0.4 0.47 0.28 -0.4 0.47" size="0.1" rgba="0.20 0.22 0.28 1" contype="0" conaffinity="0" group="2"/>
      <geom type="capsule" fromto="0.09 -0.4 0.47 0.09 -0.02 0.45" size="0.07" rgba="0.20 0.22 0.28 1" contype="0" conaffinity="0" group="2"/>
      <geom type="capsule" fromto="0.27 -0.4 0.47 0.27 -0.02 0.45" size="0.07" rgba="0.20 0.22 0.28 1" contype="0" conaffinity="0" group="2"/>
      <geom type="capsule" fromto="0.09 -0.02 0.45 0.09 0 0.07" size="0.055" rgba="0.20 0.22 0.28 1" contype="0" conaffinity="0" group="2"/>
      <geom type="capsule" fromto="0.27 -0.02 0.45 0.27 0 0.07" size="0.055" rgba="0.20 0.22 0.28 1" contype="0" conaffinity="0" group="2"/>
      <geom type="capsule" fromto="0.09 0 0.05 0.09 0.12 0.04" size="0.04" rgba="0.86 0.66 0.52 1" contype="0" conaffinity="0" group="2"/>
      <geom type="capsule" fromto="0.27 0 0.05 0.27 0.12 0.04" size="0.04" rgba="0.86 0.66 0.52 1" contype="0" conaffinity="0" group="2"/>
      <geom type="box" pos="0.18 -0.4 0.19" size="0.22 0.2 0.19" rgba="0.34 0.30 0.27 1" contype="0" conaffinity="0" group="2"/>
    </body>
    <body name="target_marker" pos="0.0 0.1 0.63">
      <geom type="sphere" size="0.03" rgba="0.1 0.9 0.2 0.85" contype="0" conaffinity="0"/>
    </body>
  </worldbody>
  <contact>
    <exclude body1="mount" body2="arm"/>
  </contact>
  <actuator>
    <position name="act_shoulder_flex" joint="shoulder_flex" kp="220" kv="18"
              ctrlrange="-1.571 2.094" forcerange="-150 150"/>
    <position name="act_shoulder_abduct" joint="shoulder_abduct" kp="220" kv="18"
              ctrlrange="-1.047 1.571" forcerange="-150 150"/>
  </actuator>
</mujoco>
